<?xml version="1.0"?>
<robot xmlns:xacro="http://www.ros.org/wiki/xacro" >
    <xacro:include filename="inertial_macros.xacro" />

    <material name="white">
        <color rgba="1 1 1 1" />
    </material>

    <material name="orange">
        <color rgba="1 0.3 0.1 1"/>
    </material>

    <material name="blue">
        <color rgba="0.2 0.2 1 1"/>
    </material>

    <material name="black">
        <color rgba="0 0 0 1"/>
    </material>

    <material name="red">
        <color rgba="1 0 0 1"/>
    </material>

    <!-- BASE LINK -->

    <link name="base_link">
      
    </link>

    <joint name="chassis_joint" type="fixed">
        <parent link="base_link"/>
        <child link="chassis"/>
        <origin xyz="0 0 0"/>
        <dynamics damping="1" friction="1"/>
    </joint>

    <gazebo reference="chassis">
        <material>Gazebo/Orange</material>
    </gazebo>

    <!-- CHASSIS body -->

    <link name="chassis">
        <visual>
            <origin xyz="0 0 0.0410" rpy="0 0 0"/>
            <geometry>
                <mesh filename="file:///home/muay/my_project_ws/src/articubot_one/description/Body.dae" scale = "10 10 10"/>
            </geometry>
            <material name="white"/>
        </visual>
        <collision>
            <origin xyz="0 0 0.0410" rpy="0 0 0"/>
            <geometry>
                <mesh filename="file:///home/muay/my_project_ws/src/articubot_one/description/Body.dae" scale = "10 10 10"/>
            </geometry>
        </collision>
        <xacro:inertial_box mass="3" x="0.05" y="0.05" z="0.15">
            <origin xyz="0 0 0.09" rpy="0 0 0"/>
        </xacro:inertial_box>
    </link>

    <!-- LEFT FRONT WHEEL -->

    <joint name="left_front_wheel_joint" type="continuous"> 
        <parent link="base_link"/> 
        <child link="left_front_wheel"/> 
        <origin xyz="0.13185 -0.2 0.05" rpy="0 0 ${pi/2} "/> 
        <axis xyz="0 -1 0"/>  <!-- axis = แกนหมุน -->
        <dynamics damping="1" friction="1"/>
    </joint>
    <link name="left_front_wheel"> 
        <visual>
            <geometry>
                <mesh filename="file:///home/muay/my_project_ws/src/articubot_one/description/wheel_final.dae"/>
            </geometry>
            <material name="blue"/> 
        </visual>
        <collision> 
            <geometry>
                <mesh filename="file:///home/muay/my_project_ws/src/articubot_one/description/wheel_final.dae"/>
            </geometry>
        </collision>
        <xacro:inertial_cylinder mass="0.5" length="0.02" radius="0.05"> 
            <origin xyz="0 0 0" rpy="${pi/2} ${pi/2} 0"/>
        </xacro:inertial_cylinder>
    </link>
    <gazebo reference="left_front_wheel">
        <material>Gazebo/Blue</material>
        <mu1 value="0.1"/>
        <mu2 value="0.1"/>
    </gazebo>

   <!-- LEFT BACK WHEEL -->

    <joint name="left_back_wheel_joint" type="continuous">
        <parent link="base_link"/> 
        <child link="left_back_wheel"/> 
        <origin xyz="0.13185 0.15 0.05" rpy="0 0 ${pi/2}"/> 
        <axis xyz="0 -1 0"/> 
        <dynamics damping="1" friction="1"/>
    </joint>
    <link name="left_back_wheel"> 
        <visual>
            <geometry>
                <mesh filename="file:///home/muay/my_project_ws/src/articubot_one/description/wheel_final.dae"/>
            </geometry>
            <material name="blue"/> 
        </visual>
        <collision> 
            <geometry>
                <mesh filename="file:///home/muay/my_project_ws/src/articubot_one/description/wheel_final.dae"/>
            </geometry>
        </collision>
        <xacro:inertial_cylinder mass="0.5" length="0.02" radius="0.05"> 
            <origin xyz="0 0 0" rpy="${pi/2} ${pi/2} 0"/>
        </xacro:inertial_cylinder>
    </link>
    <gazebo reference="left_back_wheel">
        <material>Gazebo/Blue</material>
        <mu1 value="0.1"/>
        <mu2 value="0.1"/>
    </gazebo>


    <!-- RIGHT FRONT WHEEL -->  

    <joint name="right_front_wheel_joint" type="continuous"> 
        <parent link="base_link"/> 
        <child link="right_front_wheel"/> 
        <origin xyz="-0.13185 -0.2 0.05" rpy="0 0 ${pi/2} "/> 
        <axis xyz="0 -1 0"/>
        <dynamics damping="1" friction="1"/>
    </joint>
    <link name="right_front_wheel"> 
        <visual>
            <geometry>
                <mesh filename="file:///home/muay/my_project_ws/src/articubot_one/description/wheel_final.dae"/>
            </geometry>
            <material name="blue"/> 
        </visual>
        <collision> 
            <geometry>
                <mesh filename="file:///home/muay/my_project_ws/src/articubot_one/description/wheel_final.dae"/>
            </geometry>
        </collision>
        <xacro:inertial_cylinder mass="0.5" length="0.02" radius="0.05"> 
            <origin xyz="0 0 0" rpy="${pi/2} ${pi/2} 0"/>
        </xacro:inertial_cylinder>
    </link>
    <gazebo reference="right_front_wheel">
        <material>Gazebo/Blue</material>
        <mu1 value="0.1"/>
        <mu2 value="0.1"/>
    </gazebo>


    <!-- RIGHT BACK WHEEL -->

    <joint name="right_back_wheel_joint" type="continuous"> 
        <parent link="base_link"/> 
        <child link="right_back_wheel"/> 
        <origin xyz="-0.13185  0.15 0.05" rpy="0 0 ${pi/2} "/> 
        <axis xyz="0 -1 0"/> 
        <dynamics damping="1" friction="1"/>
    </joint>
    <link name="right_back_wheel"> 
        <visual>
            <geometry>
                <mesh filename="file:///home/muay/my_project_ws/src/articubot_one/description/wheel_final.dae"/>
            </geometry>
            <material name="blue"/> 
        </visual>
        <collision> 
            <geometry>
                <mesh filename="file:///home/muay/my_project_ws/src/articubot_one/description/wheel_final.dae"/>
            </geometry>
        </collision>
        <xacro:inertial_cylinder mass="0.5" length="0.02" radius="0.05"> 
            <origin xyz="0 0 0" rpy="${pi/2} ${pi/2} 0"/>
        </xacro:inertial_cylinder>
    </link>
    <gazebo reference="right_back_wheel">
        <material>Gazebo/Blue</material>
        <mu1 value="0.1"/>
        <mu2 value="0.1"/>
    </gazebo>


     <!-- Arm Joint 1 -->
    <joint name="arm_1_joint" type="fixed">
        <parent link="chassis"/>
        <child link="arm_1"/>
        <origin xyz="0 -0.17 0.143" rpy="0 0 0"/>
        <axis xyz="0 0 1"/>
        <limit lower = "-3.14" upper = "3.14" effort = "0.5" velocity="0.5" />
        <dynamics damping="1" friction="1"/>
    </joint>

    <link name="arm_1">
        <visual>
            <geometry>
                <mesh filename="file:///home/muay/my_project_ws/src/articubot_one/description/Robot_Arm1.dae"/>
            </geometry>
        </visual>
        <collision>
            <geometry>
                <mesh filename="file:///home/muay/my_project_ws/src/articubot_one/description/Robot_Arm1.dae"/>
            </geometry>
        </collision>
        <xacro:inertial_cylinder mass="0.05" length="0.01" radius="0.01">
            <origin xyz="0 0 0" rpy="0 0 0"/>
        </xacro:inertial_cylinder>
    </link>

    <gazebo reference="arm_1">
        <material>Gazebo/Orange</material>
        <mu1 value="0.1"/>
        <mu2 value="0.1"/>
    </gazebo>
    
    <!-- Arm Joint 2 -->

    <joint name="arm_2_joint" type="revolute">
        <parent link="arm_1"/>
        <child link="arm_2"/>
        <origin xyz="0 0 0.08" rpy="0 0 -${pi/2}"/>
        <axis xyz="0 1 0"/>
        <limit lower = "-0.12" upper = "2.0" effort = "0.5" velocity="0.5" />
        <dynamics damping="1" friction="1"/>
    </joint>

    <link name="arm_2">
        <visual>
            <geometry>
                <mesh filename="file:///home/muay/my_project_ws/src/articubot_one/description/Robot_Arm2.dae"/>
            </geometry>
        </visual>
        <collision>
            <geometry>
                <mesh filename="file:///home/muay/my_project_ws/src/articubot_one/description/Robot_Arm2.dae"/>
            </geometry>
        </collision>
        <xacro:inertial_cylinder mass="0.05" length="0.01" radius="0.01">
            <origin xyz="0 0 0" rpy="0 0 0"/>
        </xacro:inertial_cylinder>
    </link>

    <gazebo reference="arm_2">
        <material>Gazebo/Orange</material>
        <mu1 value="0.1"/>
        <mu2 value="0.1"/>
    </gazebo>

    <!-- Arm Joint 3 -->

    <joint name="arm_3_joint" type="revolute">
        <parent link="arm_2"/>
        <child link="arm_3"/>
        <origin xyz="0 0 0.07" rpy="0 0 0"/>
        <axis xyz="0 1 0"/>
        <limit lower = "-2.66" upper = "2.66" effort = "0.5" velocity="0.5" />
        <dynamics damping="1" friction="1"/>
    </joint>

    <link name="arm_3">
        <visual>
            <geometry>
                <mesh filename="file:///home/muay/my_project_ws/src/articubot_one/description/Robot_Arm3.dae"/>
            </geometry>
        </visual>
        <collision>
            <geometry>
                <mesh filename="file:///home/muay/my_project_ws/src/articubot_one/description/Robot_Arm3.dae"/>
            </geometry>
        </collision>
        <xacro:inertial_cylinder mass="0.05" length="0.01" radius="0.01">
            <origin xyz="0 0 0" rpy="0 0 0"/>
        </xacro:inertial_cylinder>
    </link>

    <gazebo reference="arm_3">
        <material>Gazebo/Orange</material>
        <mu1 value="0.1"/>
        <mu2 value="0.1"/>
    </gazebo>

    <!-- Arm Joint 4 -->

    <joint name="arm_4_joint" type="revolute">
        <parent link="arm_3"/>
        <child link="arm_4"/>
        <origin xyz="0 0 0.075" rpy="-${pi} 0 -${pi}"/>
        <axis xyz="0 0 1"/>
        <limit lower = "-3.14" upper = "3.14" effort = "0.5" velocity="0.5" />
        <dynamics damping="1" friction="1"/>
    </joint>

    <link name="arm_4">
        <visual>
            <geometry>
                <mesh filename="file:///home/muay/my_project_ws/src/articubot_one/description/Robot_Arm4.dae"/>
            </geometry>
        </visual>
        <collision>
            <geometry>
                <mesh filename="file:///home/muay/my_project_ws/src/articubot_one/description/Robot_Arm4.dae"/>
            </geometry>
        </collision>
        <xacro:inertial_cylinder mass="0.05" length="0.01" radius="0.01">
            <origin xyz="0 0 0" rpy="0 0 0"/>
        </xacro:inertial_cylinder>
    </link>

    <gazebo reference="arm_4">
        <material>Gazebo/Orange</material>
        <mu1 value="0.1"/>
        <mu2 value="0.1"/>
    </gazebo>

    <!-- Arm Joint 5 -->

    <joint name="arm_5_joint" type="fixed">
        <parent link="arm_4"/>
        <child link="arm_5"/>
        <origin xyz="0 0 0.0" rpy="0 -${pi} -${pi/2}"/>
        <axis xyz="0 1 0"/>
        <limit lower = "-3.14" upper = "3.14" effort = "1" velocity="1" />
        <dynamics damping="1" friction="1"/>
    </joint>

    <link name="arm_5">
        <visual>
            <geometry>
                <mesh filename="file:///home/muay/my_project_ws/src/articubot_one/description/Robot_Arm5.dae"/>
            </geometry>
        </visual>
        <collision>
            <geometry>
                <mesh filename="file:///home/muay/my_project_ws/src/articubot_one/description/Robot_Arm5.dae"/>
            </geometry>
        </collision>
        <xacro:inertial_cylinder mass="0.05" length="0.01" radius="0.01">
            <origin xyz="0 0 0" rpy="0 0 0"/>
        </xacro:inertial_cylinder>
    </link>

    <gazebo reference="arm_5">
        <material>Gazebo/Orange</material>
        <mu1 value="0.1"/>
        <mu2 value="0.1"/>
    </gazebo>

    <!-- GRIP -->
    <!-- Grip 1 -->

    <joint name="grip_1_joint" type="revolute">
        <parent link="arm_5"/>
        <child link="grip_1"/>
        <origin xyz="0.02 0 0.02" rpy="0 0 0"/>
        <axis xyz="0 1 0"/>
        <limit lower = "-0.52" upper = "1.74" effort = "1" velocity="0.01" />
        <dynamics damping="1" friction="1"/>
    </joint>

    <link name="grip_1">
        <visual>
            <geometry>
                <mesh filename="file:///home/muay/my_project_ws/src/articubot_one/description/Robot_Armgrip1.dae"/>
            </geometry>
        </visual>
        <collision>
            <geometry>
                <mesh filename="file:///home/muay/my_project_ws/src/articubot_one/description/Robot_Armgrip1.dae"/>
            </geometry>
        </collision>
        <xacro:inertial_cylinder mass="0.05" length="0.01" radius="0.01">
            <origin xyz="0 0 0" rpy="0 0 0"/>
        </xacro:inertial_cylinder>
    </link>

    <gazebo reference="grip_1">
        <material>Gazebo/Red</material>
        <mu1 value="0.1"/>
        <mu2 value="0.1"/>
    </gazebo>

    <!-- Grip 2 -->

    <joint name="grip_2_joint" type="revolute">
        <parent link="arm_5"/>
        <child link="grip_2"/>
        <origin xyz="-0.02 0 0.02" rpy="0 0 0"/>
        <axis xyz="0 1 0"/>
        <limit lower = "-1.74" upper = "0.52" effort = "1" velocity="0.01" />
        <dynamics damping="1" friction="1"/>
    </joint>

    <link name="grip_2">
        <visual>
            <geometry>
                <mesh filename="file:///home/muay/my_project_ws/src/articubot_one/description/Robot_Armgrip2.dae"/>
            </geometry>
        </visual>
        <collision>
            <geometry>
                <mesh filename="file:///home/muay/my_project_ws/src/articubot_one/description/Robot_Armgrip2.dae"/>
            </geometry>
        </collision>
        <xacro:inertial_cylinder mass="0.05" length="0.01" radius="0.01">
            <origin xyz="0 0 0" rpy="0 0 0"/>
        </xacro:inertial_cylinder>
    </link>

    <gazebo reference="grip_2">
        <material>Gazebo/Red</material>
        <mu1 value="0.1"/>
        <mu2 value="0.1"/>
    </gazebo>

</robot>
